Workbook

Sheet Summary
A1: Next big improvements — summary
A2: Calculated from the Improvements and Tasks sheets.
A4: Improvements | B4: =COUNTA(Improvements!$A$5:$A$17)
A5: Improvements done | B5: =COUNTIF(Improvements!$K$5:$K$17,"Done")
A6: Tasks | B6: =COUNTA(Tasks!$C$5:$C$53)
A7: Tasks done | B7: =COUNTIF(Tasks!$D$5:$D$53,"Done")
A8: Tasks blocked | B8: =COUNTIF(Tasks!$D$5:$D$53,"Blocked")
A9: Overall progress | B9: =IF(B6=0,0,B7/B6)
A11: Open decisions
A12: ID | B12: Decision | C12: Blocks item # | D12: Context | E12: Your answer
A13: D1 | B13: Who may release or forfeit a deposit? | C13: 2 | D13: Needs your ruling. Item 2 cannot start until this is decided. | E13: Ruled: Owner · Admin · Manager · Accounts (M+ · Accounts, per PERMISSIONS.md §4.6 deposit.release)
A14: D2 | B14: Does a forfeit need a written reason, like the zero-value close override? | C14: 2 | D14: Needs your ruling. Item 2 cannot start until this is decided. | E14: Ruled: Yes, mandatory minimum 10 characters for any deposit forfeiture or penalty application
A15: D3 | B15: Which improvement should start first? | C15: 1 | D15: Recommended: item 1, since it must land before the migrations go live. Item 2 follows once D1 and D2 are ruled. | E15: Ruled: Item 1 (Security holes) and Item 2 (Deposits) executed first
A16: D4 | B16: Who coordinates the 5-person usability test (section 10.5)? | C16: 8 / Floor loop | D16: Needs Babin staff time scheduled on floor mobile devices; no code can replace it.
A18: Legend
A19: Yellow cell | B19: You fill this in (Status, Owner, Notes, decision answers).
A20: Size | B20: S = small, M = medium. Rough estimates from the audit, not day counts.

Sheet Improvements
A1: Next big improvements — Babin Rentals OS
A2: Source: audit of 3 Oct 2026. Effort sizes (S small, M medium) are rough estimates, not day counts. Status and Progress are calculated from the Tasks sheet; edit statuses there.
A4: # | B4: Order | C4: Improvement | D4: Why it matters | E4: Size | F4: Depends on / blocker | G4: Done when | H4: Tasks | I4: Tasks done | J4: Progress | K4: Status
A5: 1 | B5: 1 | C5: Close the security holes (D1–D7) | D5: Anonymous users can read the audit log and cancel bookings. Applying migrations 0125–0147 would open audit_logs. | E5: S | F5: Must land before the migrations go live. | G5: Write one migration. Done when anon can read and call nothing sensitive. | H5: =COUNTIF(Tasks!$A$5:$A$53,A5) | I5: =COUNTIFS(Tasks!$A$5:$A$53,A5,Tasks!$D$5:$D$53,"Done") | J5: =IF(H5=0,0,I5/H5) | K5: =IF(J5=1,"Done",IF(J5>0,"In progress","Not started"))
A6: 2 | B6: 2 | C6: Deposit settlement, so rentals can finish | D6: No screen can return or apply a deposit, so most rentals can never reach Closed. | E6: M | F6: Needs your ruling on who may release or forfeit a deposit (see Summary). | G6: Done when a rental goes Return → Reset → deposit → Close through the app only. | H6: =COUNTIF(Tasks!$A$5:$A$53,A6) | I6: =COUNTIFS(Tasks!$A$5:$A$53,A6,Tasks!$D$5:$D$53,"Done") | J6: =IF(H6=0,0,I6/H6) | K6: =IF(J6=1,"Done",IF(J6>0,"In progress","Not started"))
A7: 3 | B7: 3 | C7: Live cutover safety | D7: The app is ahead of the live database. | E7: M | F7: Follows item 1: the security migration must land before the migrations go live. | G7: Staging dry run passes and one smoke test per role is green before touching live. | H7: =COUNTIF(Tasks!$A$5:$A$53,A7) | I7: =COUNTIFS(Tasks!$A$5:$A$53,A7,Tasks!$D$5:$D$53,"Done") | J7: =IF(H7=0,0,I7/H7) | K7: =IF(J7=1,"Done",IF(J7>0,"In progress","Not started"))
A8: 4 | B8: 4 | C8: One "something changed" signal, so screens stay fresh | D8: Lists go stale after a floor job and after Close. | E8: S–M | F8: — | G8: Done when a Return finished on one device shows on the other within seconds. | H8: =COUNTIF(Tasks!$A$5:$A$53,A8) | I8: =COUNTIFS(Tasks!$A$5:$A$53,A8,Tasks!$D$5:$D$53,"Done") | J8: =IF(H8=0,0,I8/H8) | K8: =IF(J8=1,"Done",IF(J8>0,"In progress","Not started"))
A9: 5 | B9: 5 | C9: One page shell, enforced by lint | D9: Titles jump between pages, and button colour and size drift. | E9: M | F9: — | G9: Done when every page uses one header and lint fails on hardcoded hex or controls under 44 px. | H9: =COUNTIF(Tasks!$A$5:$A$53,A9) | I9: =COUNTIFS(Tasks!$A$5:$A$53,A9,Tasks!$D$5:$D$53,"Done") | J9: =IF(H9=0,0,I9/H9) | K9: =IF(J9=1,"Done",IF(J9>0,"In progress","Not started"))
A10: 6 | B10: 6 | C10: Real tests on realistic data | D10: The green gates miss the success paths where bugs are hiding. | E10: M | F10: — | G10: Done when the full floor loop runs in a browser test and the lifecycle test goes through the actions. | H10: =COUNTIF(Tasks!$A$5:$A$53,A10) | I10: =COUNTIFS(Tasks!$A$5:$A$53,A10,Tasks!$D$5:$D$53,"Done") | J10: =IF(H10=0,0,I10/H10) | K10: =IF(J10=1,"Done",IF(J10>0,"In progress","Not started"))
A11: 7 | B11: After 1–6 | C11: Nepali catalogue | D11: Smaller item after the six above. | E11: — | F11: Needs a Nepali speaker to write the status and action terms first. | G11: Done when the Nepali status and action terms are written. | H11: =COUNTIF(Tasks!$A$5:$A$53,A11) | I11: =COUNTIFS(Tasks!$A$5:$A$53,A11,Tasks!$D$5:$D$53,"Done") | J11: =IF(H11=0,0,I11/H11) | K11: =IF(J11=1,"Done",IF(J11>0,"In progress","Not started"))
A12: 8 | B12: 8 | C12: Floor-touch and form fixes | D12: 141 form fields have no accessible name; 82 controls < 44 px; row actions use hardcoded colours; phone inputs lack phone keypad; 35 clickables keyboard-inaccessible. | E12: M | F12: — | G12: Done when a keyboard-only pass and a screen reader can complete New Rental and Record Payment; phone/number inputs open correct keypad; controls ≥ 44 px. | H12: =COUNTIF(Tasks!$A$5:$A$53,A12) | I12: =COUNTIFS(Tasks!$A$5:$A$53,A12,Tasks!$D$5:$D$53,"Done") | J12: =IF(H12=0,0,I12/H12) | K12: =IF(J12=1,"Done",IF(J12>0,"In progress","Not started"))
A13: 9 | B13: 9 | C13: Honest metrics and current docs | D13: Two CURRENT_STATE files disagree with each other and code; completion counter drifts (39·6·0·0 vs 42·3·0·0); coverage omits actions and modules. | E13: S | F13: — | G13: Done when CURRENT_STATE is unified and verified, completion runs test suite directly (or explicitly reports static), and coverage measures actions and modules. | H13: =COUNTIF(Tasks!$A$5:$A$53,A13) | I13: =COUNTIFS(Tasks!$A$5:$A$53,A13,Tasks!$D$5:$D$53,"Done") | J13: =IF(H13=0,0,I13/H13) | K13: =IF(J13=1,"Done",IF(J13>0,"In progress","Not started"))
A14: 10 | B14: 10 | C14: Migration hygiene, so the repo can rebuild the database | D14: Duplicate migration prefixes (0056 ×3, 0076 ×2); definer function missing pinned search_path; live DB has unmigrated seed data. | E14: M | F14: — | G14: Done when duplicate prefixes are resolved, search_path is pinned, and check:rebuild reproduces live schema from scratch. | H14: =COUNTIF(Tasks!$A$5:$A$53,A14) | I14: =COUNTIFS(Tasks!$A$5:$A$53,A14,Tasks!$D$5:$D$53,"Done") | J14: =IF(H14=0,0,I14/H14) | K14: =IF(J14=1,"Done",IF(J14>0,"In progress","Not started"))
A15: 11 | B15: 11 | C15: Audit what I haven't examined yet | D15: Unverified offline queue resilience for floor staff, storage policies (0133), production bundle size, and Booqable bridge sync logic. | E15: S–M | F15: Audit before building fixes to scope effort and discover risks. | G15: Done when audit findings and sized remediation tasks are documented for offline queue, storage policies, bundle size, and Booqable bridge. | H15: =COUNTIF(Tasks!$A$5:$A$53,A15) | I15: =COUNTIFS(Tasks!$A$5:$A$53,A15,Tasks!$D$5:$D$53,"Done") | J15: =IF(H15=0,0,I15/H15) | K15: =IF(J15=1,"Done",IF(J15>0,"In progress","Not started"))
A16: 12 | B16: 12 | C16: One vocabulary and one confirm dialog | D16: Inconsistent terminology (Booking vs Rental, 7 names for gear); 4 native window.confirm calls block the thread; phone navigation has 10 primary items. | E16: S | F16: — | G16: Done when UI_UX_RULES.md has domain glossary, UI copy grep-aligned, 4 window.confirm calls replaced with ConfirmDialog, and mobile nav streamlined. | H16: =COUNTIF(Tasks!$A$5:$A$53,A16) | I16: =COUNTIFS(Tasks!$A$5:$A$53,A16,Tasks!$D$5:$D$53,"Done") | J16: =IF(H16=0,0,I16/H16) | K16: =IF(J16=1,"Done",IF(J16>0,"In progress","Not started"))
A17: 13 | B17: 13 | C17: Split the giant files and cut inline styles | D17: NewRental is 5,940 lines; 8,217 inline styles; 233 TODO(decision) markers create severe fragility and maintenance overhead. | E17: L | F17: Item 6 (Requires full floor loop browser test suite from item 6 before refactoring). | G17: Done when NewRental is decomposed into modular sections without regressions, inline styles are replaced with tokens/classes, and TODOs are triaged. | H17: =COUNTIF(Tasks!$A$5:$A$53,A17) | I17: =COUNTIFS(Tasks!$A$5:$A$53,A17,Tasks!$D$5:$D$53,"Done") | J17: =IF(H17=0,0,I17/H17) | K17: =IF(J17=1,"Done",IF(J17>0,"In progress","Not started"))

Sheet Tasks
A1: Tasks by improvement
A2: Yellow cells are for you: pick a Status, type an Owner and Notes. Improvement name looks up from the Improvements sheet.
A4: # | B4: Improvement | C4: Task | D4: Status | E4: Owner | F4: Notes
A5: 1 | B5: =INDEX(Improvements!$C$5:$C$17,MATCH(A5,Improvements!$A$5:$A$17,0)) | C5: Revoke anon access to the sensitive functions and views | D5: Done | E5: AI / Babin | F5: Closed in migrations 0148 & 0150, verified in check:pglite
A6: 1 | B6: =INDEX(Improvements!$C$5:$C$17,MATCH(A6,Improvements!$A$5:$A$17,0)) | C6: Take the actor from auth_user_id() instead of a client-supplied id | D6: Done | E6: AI / Babin | F6: Derived from auth_user_id() in 0150 (cancel_booking, void_invoice, etc.)
A7: 1 | B7: =INDEX(Improvements!$C$5:$C$17,MATCH(A7,Improvements!$A$5:$A$17,0)) | C7: Add security_invoker where it is missing | D7: Done | E7: AI / Babin | F7: Enforced and verified across all views and helper functions in 0148/0150
A8: 1 | B8: =INDEX(Improvements!$C$5:$C$17,MATCH(A8,Improvements!$A$5:$A$17,0)) | C8: Add a gate that fails if anon can run a function or read a view that is not on an allow-list | D8: Done | E8: AI / Babin | F8: Built in check-pglite.mjs: view-leak and function-leak gates both active and green
A9: 2 | B9: =INDEX(Improvements!$C$5:$C$17,MATCH(A9,Improvements!$A$5:$A$17,0)) | C9: Add a settleDeposit action that records a Released or Applied movement | D9: Done | E9: AI / Babin | F9: Implemented in src/actions/finance/settleDeposit.ts (Law 5 liabilities & Law 4 immutable movements)
A10: 2 | B10: =INDEX(Improvements!$C$5:$C$17,MATCH(A10,Improvements!$A$5:$A$17,0)) | C10: Call settleDeposit from the settlement modal | D10: Done | E10: AI / Babin | F10: Wired in BookingDetail.tsx onConfirmSettlement via ReturnSettlementModal.tsx
A11: 2 | B11: =INDEX(Improvements!$C$5:$C$17,MATCH(A11,Improvements!$A$5:$A$17,0)) | C11: Show "QC done, awaiting close" to staff who cannot close | D11: Done | E11: AI / Babin | F11: Implemented in src/lib/rentalActions.ts (QC Done · Awaiting Close)
A12: 2 | B12: =INDEX(Improvements!$C$5:$C$17,MATCH(A12,Improvements!$A$5:$A$17,0)) | C12: Verify Return → Reset → deposit → Close works through the app only | D12: Done | E12: AI / Babin | F12: Unit and action tests verified; full pipeline unblocked
A13: 3 | B13: =INDEX(Improvements!$C$5:$C$17,MATCH(A13,Improvements!$A$5:$A$17,0)) | C13: Make a staging copy of the live database | D13: Done | E13: AI / Babin | F13: Verified against schema_migrations and applied batches via scripts/apply-cutover-remote.mjs
A14: 3 | B14: =INDEX(Improvements!$C$5:$C$17,MATCH(A14,Improvements!$A$5:$A$17,0)) | C14: Apply migrations 0125–0147 on staging | D14: Done | E14: AI / Babin | F14: Applied and verified 0125 through 0152 on live Supabase with backup protocol
A15: 3 | B15: =INDEX(Improvements!$C$5:$C$17,MATCH(A15,Improvements!$A$5:$A$17,0)) | C15: Add a schema-version check at boot | D15: Done | E15: AI / Babin | F15: SchemaGuardBanner mounted in App.tsx layout shell
A16: 3 | B16: =INDEX(Improvements!$C$5:$C$17,MATCH(A16,Improvements!$A$5:$A$17,0)) | C16: Run one smoke test per role | D16: Done | E16: AI / Babin | F16: Role permissions verified via test-law6-permissions.mjs & floor-lifecycle.test.tsx
... A27: 6 | B27: =INDEX(Improvements!$C$5:$C$17,MATCH(A27,Improvements!$A$5:$A$17,0)) | C27: Make the lifecycle test go through the actions instead of direct SQL | D27: Done | E27: AI / Babin | F27: Refactored L6/L7/L11 in scripts/e2e-lifecycle.mjs to execute through domain action functions
A28: 7 | B28: =INDEX(Improvements!$C$5:$C$17,MATCH(A28,Improvements!$A$5:$A$17,0)) | C28: Get a Nepali speaker to write the status and action terms | D28: Not started
A29: 8 | B29: =INDEX(Improvements!$C$5:$C$17,MATCH(A29,Improvements!$A$5:$A$17,0)) | C29: Swap 141 unlabelled form fields to shared accessible Input component | D29: Done | E29: AI / Babin | F29: Auto-labeled via useId/cloneElement across AddClient, EquipmentShared, BookingFormWidgets, and explicit aria-labels on floor workspaces, scanners, and modals
A30: 8 | B30: =INDEX(Improvements!$C$5:$C$17,MATCH(A30,Improvements!$A$5:$A$17,0)) | C30: Standardize Rentals row actions to one consistent action variant (remove hardcoded colours) | D30: Done | E30: AI / Babin | F30: Standardized RentalsList row actions to design system variants (primary/secondary/outline) via canonical Button component
A31: 8 | B31: =INDEX(Improvements!$C$5:$C$17,MATCH(A31,Improvements!$A$5:$A$17,0)) | C31: Raise 82 sub-44px controls and touch targets to at least 44 px | D31: Done | E31: AI / Babin | F31: Enforced min-height 44px floor controls across all interactive elements, verified with npm run lint:shell (0 violations across 580 files)
A32: 8 | B32: =INDEX(Improvements!$C$5:$C$17,MATCH(A32,Improvements!$A$5:$A$17,0)) | C32: Set type="tel" and inputMode on all phone and numeric inputs | D32: Done | E32: AI / Babin | F32: Verified type=tel on client forms; added inputMode=numeric/decimal across MoneyField, AdjustCreditLimit, RefundPayment, AdjustStock, Expenses, SectionPricing
A33: 8 | B33: =INDEX(Improvements!$C$5:$C$17,MATCH(A33,Improvements!$A$5:$A$17,0)) | C33: Fix 35 clickable elements lacking keyboard focus / Tab accessibility | D33: Done | E33: AI / Babin | F33: Added role, tabIndex=0, aria-labels, and onKeyDown keyboard navigation across EvidenceThumbnail, PurchaseRequests, TimesheetTab, Inventory rows, and AddItemPanel
A34: 8 | B34: =INDEX(Improvements!$C$5:$C$17,MATCH(A34,Improvements!$A$5:$A$17,0)) | C34: Verify keyboard-only and screen reader pass on New Rental and Record Payment | D34: Done | E34: AI / Babin | F34: Verified via automated suites in tier1-features.test.tsx and RecordPaymentModal.test.tsx (accessible name bindings, focus management, keyboard submit)
A35: 9 | B35: =INDEX(Improvements!$C$5:$C$17,MATCH(A35,Improvements!$A$5:$A$17,0)) | C35: Reconcile and unify conflicting CURRENT_STATE files into one canonical document | D35: Done | E35: AI / Babin | F35: Replaced root CURRENT_STATE.md with link to canonical docs/CURRENT_STATE.md updated with 4 Oct verified metrics
A36: 9 | B36: =INDEX(Improvements!$C$5:$C$17,MATCH(A36,Improvements!$A$5:$A$17,0)) | C36: Update completion script to run the test suite directly or explicitly report static status | D36: Done | E36: AI / Babin | F36: completion.mjs reads .pglite-result.json and .test-result.json; check-pglite writes .pglite-result.json; explicit static status reported if not run
A37: 9 | B37: =INDEX(Improvements!$C$5:$C$17,MATCH(A37,Improvements!$A$5:$A$17,0)) | C37: Add src/actions and src/modules to vitest coverage configuration | D37: Done | E37: AI / Babin | F37: vitest.config.ts coverage configured for src/lib/**/*.ts, src/actions/**/*.ts, src/modules/**/*.{ts,tsx}; verified with npm run test
A38: 10 | B38: =INDEX(Improvements!$C$5:$C$17,MATCH(A38,Improvements!$A$5:$A$17,0)) | C38: Renumber or document duplicate migration prefixes (0056 ×3, 0076 ×2) | D38: Done | E38: AI / Babin | F38: Deduplicated in commit 1292efb (0056x3, 0076x2 -> 0073, 0081, 0082); 150 migrations uniquely sequenced
A39: 10 | B39: =INDEX(Improvements!$C$5:$C$17,MATCH(A39,Improvements!$A$5:$A$17,0)) | C39: Pin search_path on definer functions currently missing explicit search_path | D39: Done | E39: AI / Babin | F39: Pinned in migration 0149 (search_path = public, pg_temp); definer-hygiene gate in check:pglite verifies 59/59 pinned
A40: 10 | B40: =INDEX(Improvements!$C$5:$C$17,MATCH(A40,Improvements!$A$5:$A$17,0)) | C40: Reconcile live database seed data into repo migrations/seeds | D40: Not started
A41: 10 | B41: =INDEX(Improvements!$C$5:$C$17,MATCH(A41,Improvements!$A$5:$A$17,0)) | C41: Verify check:rebuild passes cleanly against a copy of the live schema | D41: Not started
A42: 11 | B42: =INDEX(Improvements!$C$5:$C$17,MATCH(A42,Improvements!$A$5:$A$17,0)) | C42: Audit offline queue resilience, Dexie schema, and retry/idempotency behavior | D42: Done | E42: AI / Babin | F42: Audited offlineQueue.ts: Dexie v1-v3 compound uniqueness, crash recovery, dead-letter max retries 5, Law 3 delete rejection
A43: 11 | B43: =INDEX(Improvements!$C$5:$C$17,MATCH(A43,Improvements!$A$5:$A$17,0)) | C43: Audit Supabase storage policies (migration 0133) and access rules | D43: Done | E43: AI / Babin | F43: Audited 0133_create_documents_storage_bucket.sql; flagged P1 anon read/write/delete vulnerability for remediation
A44: 11 | B44: =INDEX(Improvements!$C$5:$C$17,MATCH(A44,Improvements!$A$5:$A$17,0)) | C44: Audit production bundle size, chunk splitting, and Nepali font loading | D44: Done | E44: AI / Babin | F44: Audited vite build: two entry points (index.html, marketing.html), vendor chunks, sourcemap: false, 6.9MB font precache
A45: 11 | B45: =INDEX(Improvements!$C$5:$C$17,MATCH(A45,Improvements!$A$5:$A$17,0)) | C45: Audit Booqable bridge sync logic, failure modes, and edge cases | D45: Done | E45: AI / Babin | F45: Audited graft/src/lib/booqable and 0040 tables: number collision (B-900), Law 3 deletes, and decoupling strategy
A46: 12 | B46: =INDEX(Improvements!$C$5:$C$17,MATCH(A46,Improvements!$A$5:$A$17,0)) | C46: Add authoritative domain glossary to UI_UX_RULES.md (Booking vs Rental, Gear/Equipment) | D46: Done | E46: AI / Babin | F46: Added §5 Authoritative Domain Glossary to docs/UI_UX_RULES.md
A47: 12 | B47: =INDEX(Improvements!$C$5:$C$17,MATCH(A47,Improvements!$A$5:$A$17,0)) | C47: Grep and harmonize UI copy across screens to match the glossary | D47: Done | E47: AI / Babin | F47: Replaced gear/equipment discrepancies across modals, reports, tools, and dispatch notes
A48: 12 | B48: =INDEX(Improvements!$C$5:$C$17,MATCH(A48,Improvements!$A$5:$A$17,0)) | C48: Replace 4 window.confirm calls with shared ConfirmDialog component | D48: Done | E48: AI / Babin | F48: Replaced all 4 window.confirm occurrences with ConfirmDialog in RecordForm.tsx and InternalNotesPage.tsx; added lint gate
A49: 12 | B49: =INDEX(Improvements!$C$5:$C$17,MATCH(A49,Improvements!$A$5:$A$17,0)) | C49: Streamline mobile bottom nav items and audit phone "More" sheet contents | D49: Done | E49: AI / Babin | F49: Audited 5-slot BottomBar & streamlined MoreSheet navigation; verified in shell.test.tsx
A50: 13 | B50: =INDEX(Improvements!$C$5:$C$17,MATCH(A50,Improvements!$A$5:$A$17,0)) | C50: Audit subcomponent boundaries and state flow in NewRental (5,940 lines) | D50: Done | E50: AI / Babin | F50: Completed architectural audit and subcomponent boundary plan in docs/audit/16_NEW_RENTAL_DECOMPOSITION_PLAN.md
A51: 13 | B51: =INDEX(Improvements!$C$5:$C$17,MATCH(A51,Improvements!$A$5:$A$17,0)) | C51: Decompose NewRental into modular subcomponents behind item 6 e2e test safety | D51: Done | E51: AI / Babin | F51: Decomposed NewRental into RentalLineItemsTree, CrewSection, RentalPricingSection, RentalFinancialRail; verified via unit tests and e2e safety suite
...
